Workbook
Name Slicer_Sales_Month: #N/A

Sheet Data
A1: Transaction_ID | B1: Date | C1: Customer_ID | D1: Customer_Name | E1: Product_ID | F1: Product_Name | G1: Category | H1: Quantity | I1: Unit_Price | J1: Payment_Method | K1: Region | L1: Customer_Segment | M1: Customer_Since | N1: Total_Amount | O1: Customer relationship | P1: Timestamp | Q1: Abbreviation_Customer_Name | R1: Eomonth of sales | S1: Sales Month
A2: TRX0155 | B2: 45393 | C2: CUST023 | D2: Paul Baker | E2: P009 | F2: Monitor | G2: Electronics | H2: 3 | I2: 249.99 | J2: Cash | K2: Central | L2: Basic | M2: 44425 | N2: =data[[#This Row],[Quantity]]*data[[#This Row],[Unit_Price]] -> 749.97 | O2: =DATEDIF(M2,TODAY(),"Y") -> 5 | P2: =NOW() -> 46308.73 | Q2: {=_xlfn.TEXTJOIN("",TRUE,LEFT(_xlfn.TEXTSPLIT(data[[#This Row],[Customer_Name]]," "),1))} -> PB | R2: =EOMONTH(data[[#This Row],[Date]],0) -> 45412 | S2: =MONTH(data[[#This Row],[Date]]) -> 4
A3: TRX0023 | B3: 45396 | C3: CUST013 | D3: Joseph Jackson | E3: P009 | F3: Monitor | G3: Electronics | H3: 3 | I3: 249.99 | J3: Credit Card | K3: Central | L3: Premium | M3: 44575 | N3: =data[[#This Row],[Quantity]]*data[[#This Row],[Unit_Price]] -> 749.97 | O3: =DATEDIF(M3,TODAY(),"Y") -> 4 | P3: =NOW() -> 46308.73 | Q3: {=_xlfn.TEXTJOIN("",TRUE,LEFT(_xlfn.TEXTSPLIT(data[[#This Row],[Customer_Name]]," "),1))} -> JJ | R3: =EOMONTH(data[[#This Row],[Date]],0) -> 45412 | S3: =MONTH(data[[#This Row],[Date]]) -> 4
A4: TRX0139 | B4: 45399 | C4: CUST021 | D4: Kevin Scott | E4: P005 | F4: Blender | G4: Appliances | H4: 3 | I4: 59.99 | J4: PayPal | K4: South | L4: Standard | M4: 45262 | N4: =data[[#This Row],[Quantity]]*data[[#This Row],[Unit_Price]] -> 179.97 | O4: =DATEDIF(M4,TODAY(),"Y") -> 2 | P4: =NOW() -> 46308.73 | Q4: {=_xlfn.TEXTJOIN("",TRUE,LEFT(_xlfn.TEXTSPLIT(data[[#This Row],[Customer_Name]]," "),1))} -> KS | R4: =EOMONTH(data[[#This Row],[Date]],0) -> 45412 | S4: =MONTH(data[[#This Row],[Date]]) -> 4
A5: TRX0043 | B5: 45400 | C5: CUST046 | D5: Kathleen Bennett | E5: P005 | F5: Blender | G5: Appliances | H5: 3 | I5: 59.99 | J5: Cash | K5: North | L5: Premium | M5: 45114 | N5: =data[[#This Row],[Quantity]]*data[[#This Row],[Unit_Price]] -> 179.97 | O5: =DATEDIF(M5,TODAY(),"Y") -> 3 | P5: =NOW() -> 46308.73 | Q5: {=_xlfn.TEXTJOIN("",TRUE,LEFT(_xlfn.TEXTSPLIT(data[[#This Row],[Customer_Name]]," "),1))} -> KB | R5: =EOMONTH(data[[#This Row],[Date]],0) -> 45412 | S5: =MONTH(data[[#This Row],[Date]]) -> 4
A6: TRX0212 | B6: 45400 | C6: CUST003 | D6: Michael Brown | E6: P008 | F6: Bookshelf | G6: Furniture | H6: 5 | I6: 149.99 | J6: Credit Card | K6: North | L6: Premium | M6: 45295 | N6: =data[[#This Row],[Quantity]]*data[[#This Row],[Unit_Price]] -> 749.95 | O6: =DATEDIF(M6,TODAY(),"Y") -> 2 | P6: =NOW() -> 46308.73 | Q6: {=_xlfn.TEXTJOIN("",TRUE,LEFT(_xlfn.TEXTSPLIT(data[[#This Row],[Customer_Name]]," "),1))} -> MB | R6: =EOMONTH(data[[#This Row],[Date]],0) -> 45412 | S6: =MONTH(data[[#This Row],[Date]]) -> 4
A7: TRX0092 | B7: 45403 | C7: CUST024 | D7: Dorothy Nelson | E7: P005 | F7: Blender | G7: Appliances | H7: 2 | I7: 59.99 | J7: Cash | K7: West | L7: Standard | M7: 44746 | N7: =data[[#This Row],[Quantity]]*data[[#This Row],[Unit_Price]] -> 119.98 | O7: =DATEDIF(M7,TODAY(),"Y") -> 4 | P7: =NOW() -> 46308.73 | Q7: {=_xlfn.TEXTJOIN("",TRUE,LEFT(_xlfn.TEXTSPLIT(data[[#This Row],[Customer_Name]]," "),1))} -> DN | R7: =EOMONTH(data[[#This Row],[Date]],0) -> 45412 | S7: =MONTH(data[[#This Row],[Date]]) -> 4
A8: TRX0193 | B8: 45403 | C8: CUST024 | D8: Dorothy Nelson | E8: P003 | F8: Headphones | G8: Electronics | H8: 5 | I8: 149.99 | J8: Credit Card | K8: Central | L8: Standard | M8: 44418 | N8: =data[[#This Row],[Quantity]]*data[[#This Row],[Unit_Price]] -> 749.95 | O8: =DATEDIF(M8,TODAY(),"Y") -> 5 | P8: =NOW() -> 46308.73 | Q8: {=_xlfn.TEXTJOIN("",TRUE,LEFT(_xlfn.TEXTSPLIT(data[[#This Row],[Customer_Name]]," "),1))} -> DN | R8: =EOMONTH(data[[#This Row],[Date]],0) -> 45412 | S8: =MONTH(data[[#This Row],[Date]]) -> 4
A9: TRX0240 | B9: 45403 | C9: CUST017 | D9: Charles Allen | E9: P005 | F9: Blender | G9: Appliances | H9: 3 | I9: 59.99 | J9: Debit Card | K9: South | L9: Basic | M9: 45007 | N9: =data[[#This Row],[Quantity]]*data[[#This Row],[Unit_Price]] -> 179.97 | O9: =DATEDIF(M9,TODAY(),"Y") -> 3 | P9: =NOW() -> 46308.73 | Q9: {=_xlfn.TEXTJOIN("",TRUE,LEFT(_xlfn.TEXTSPLIT(data[[#This Row],[Customer_Name]]," "),1))} -> CA | R9: =EOMONTH(data[[#This Row],[Date]],0) -> 45412 | S9: =MONTH(data[[#This Row],[Date]]) -> 4
A10: TRX0135 | B10: 45405 | C10: CUST009 | D10: Robert Thomas | E10: P001 | F10: Laptop | G10: Electronics | H10: 3 | I10: 899.99 | J10: PayPal | K10: East | L10: Standard | M10: 45299 | N10: =data[[#This Row],[Quantity]]*data[[#This Row],[Unit_Price]] -> 2699.97 | O10: =DATEDIF(M10,TODAY(),"Y") -> 2 | P10: =NOW() -> 46308.73 | Q10: {=_xlfn.TEXTJOIN("",TRUE,LEFT(_xlfn.TEXTSPLIT(data[[#This Row],[Customer_Name]]," "),1))} -> RT | R10: =EOMONTH(data[[#This Row],[Date]],0) -> 45412 | S10: =MONTH(data[[#This Row],[Date]]) -> 4
A11: TRX0185 | B11: 45408 | C11: CUST026 | D11: Karen Hill | E11: P005 | F11: Blender | G11: Appliances | H11: 3 | I11: 59.99 | J11: Cash | K11: West | L11: Premium | M11: 45207 | N11: =data[[#This Row],[Quantity]]*data[[#This Row],[Unit_Price]] -> 179.97 | O11: =DATEDIF(M11,TODAY(),"Y") -> 3 | P11: =NOW() -> 46308.73 | Q11: {=_xlfn.TEXTJOIN("",TRUE,LEFT(_xlfn.TEXTSPLIT(data[[#This Row],[Customer_Name]]," "),1))} -> KH | R11: =EOMONTH(data[[#This Row],[Date]],0) -> 45412 | S11: =MONTH(data[[#This Row],[Date]]) -> 4
A12: TRX0138 | B12: 45408 | C12: CUST022 | D12: Susan Green | E12: P008 | F12: Bookshelf | G12: Furniture | H12: 1 | I12: 149.99 | J12: Credit Card | K12: West | L12: Standard | M12: 45103 | N12: =data[[#This Row],[Quantity]]*data[[#This Row],[Unit_Price]] -> 149.99 | O12: =DATEDIF(M12,TODAY(),"Y") -> 3 | P12: =NOW() -> 46308.73 | Q12: {=_xlfn.TEXTJOIN("",TRUE,LEFT(_xlfn.TEXTSPLIT(data[[#This Row],[Customer_Name]]," "),1))} -> SG | R12: =EOMONTH(data[[#This Row],[Date]],0) -> 45412 | S12: =MONTH(data[[#This Row],[Date]]) -> 4
A13: TRX0209 | B13: 45408 | C13: CUST046 | D13: Kathleen Bennett | E13: P008 | F13: Bookshelf | G13: Furniture | H13: 5 | I13: 149.99 | J13: Debit Card | K13: North | L13: Basic | M13: 44830 | N13: =data[[#This Row],[Quantity]]*data[[#This Row],[Unit_Price]] -> 749.95 | O13: =DATEDIF(M13,TODAY(),"Y") -> 4 | P13: =NOW() -> 46308.73 | Q13: {=_xlfn.TEXTJOIN("",TRUE,LEFT(_xlfn.TEXTSPLIT(data[[#This Row],[Customer_Name]]," "),1))} -> KB | R13: =EOMONTH(data[[#This Row],[Date]],0) -> 45412 | S13: =MONTH(data[[#This Row],[Date]]) -> 4
... A251: TRX0064 | B251: 45758 | C251: CUST031 | D251: Steven Turner | E251: P010 | F251: Keyboard | G251: Electronics | H251: 3 | I251: 89.99 | J251: Debit Card | K251: North | L251: Premium | M251: 44878 | N251: =data[[#This Row],[Quantity]]*data[[#This Row],[Unit_Price]] -> 269.97 | O251: =DATEDIF(M251,TODAY(),"Y") -> 3 | P251: =NOW() -> 46308.73 | Q251: {=_xlfn.TEXTJOIN("",TRUE,LEFT(_xlfn.TEXTSPLIT(data[[#This Row],[Customer_Name]]," "),1))} -> ST | R251: =EOMONTH(data[[#This Row],[Date]],0) -> 45777 | S251: =MONTH(data[[#This Row],[Date]]) -> 4

Sheet Analysis
A1: Analysis | D1: Customer Name | E1: Total Revenue | F1: Purchase Frequency | G1: Abbreviation_Customer_Name | I1: Top 10 Customers | N1: Product | O1: Quantity Sold | Q1: Top 3 Products
A2: Total Revenue | B2: =SUM(Data!N:N) -> 229192.47 | D2: {=_xlfn.UNIQUE(data[Customer_Name])} -> Paul Baker | E2: =SUMIF(data[Customer_Name],Analysis!D2,data[Total_Amount]) -> 8309.74 | F2: =COUNTIF(data[Customer_Name],Analysis!D2) -> 8 | G2: {=_xlfn.TEXTJOIN("",TRUE,LEFT(_xlfn.TEXTSPLIT(D2," "),1))} -> PB | I2: No. | J2: Customer Name | K2: Revenue | N2: {=_xlfn.UNIQUE(data[Product_Name])} -> Monitor | O2: =SUMIF(data[Product_Name],Analysis!N2,data[Quantity]) -> 88 | Q2: No. | R2: Product | S2: Quantity Sold
A3: Total Transactions | B3: =COUNTA(data[Transaction_ID]) -> 250 | D3: Joseph Jackson | E3: =SUMIF(data[Customer_Name],Analysis!D3,data[Total_Amount]) -> 6949.84 | F3: =COUNTIF(data[Customer_Name],Analysis!D3) -> 5 | G3: {=_xlfn.TEXTJOIN("",TRUE,LEFT(_xlfn.TEXTSPLIT(D3," "),1))} -> JJ | I3: 1 | J3: =_xlfn.XLOOKUP(K3,$E$2:$E$51,$D$2:$D$51) -> Mark Carter | K3: =LARGE(E2:E51,I3) -> 15659.65 | N3: Blender | O3: =SUMIF(data[Product_Name],Analysis!N3,data[Quantity]) -> 87 | Q3: 1 | R3: =_xlfn.XLOOKUP(S3,O2:O11,$N$2:$N$11) -> Bookshelf | S3: =LARGE($O$2:$O$11,Q3) -> 102
A4: Total Quantity | B4: =SUM(data[Quantity]) -> 753 | D4: Kevin Scott | E4: =SUMIF(data[Customer_Name],Analysis!D4,data[Total_Amount]) -> 3259.87 | F4: =COUNTIF(data[Customer_Name],Analysis!D4) -> 6 | G4: {=_xlfn.TEXTJOIN("",TRUE,LEFT(_xlfn.TEXTSPLIT(D4," "),1))} -> KS | I4: 2 | J4: =_xlfn.XLOOKUP(K4,$E$2:$E$51,$D$2:$D$51) -> Edward Mitchell | K4: =LARGE(E3:E52,I4) -> 11919.77 | N4: Bookshelf | O4: =SUMIF(data[Product_Name],Analysis!N4,data[Quantity]) -> 102 | Q4: 2 | R4: =_xlfn.XLOOKUP(S4,O3:O12,$N$2:$N$11) -> Laptop | S4: =LARGE($O$2:$O$11,Q4) -> 96
A5: Average Transaction Value | B5: =AVERAGE(data[Total_Amount]) -> 916.76988 | D5: Kathleen Bennett | E5: =SUMIF(data[Customer_Name],Analysis!D5,data[Total_Amount]) -> 4309.81 | F5: =COUNTIF(data[Customer_Name],Analysis!D5) -> 6 | G5: {=_xlfn.TEXTJOIN("",TRUE,LEFT(_xlfn.TEXTSPLIT(D5," "),1))} -> KB | I5: 3 | J5: =_xlfn.XLOOKUP(K5,$E$2:$E$51,$D$2:$D$51) -> Barbara Young | K5: =LARGE(E4:E53,I5) -> 10649.8 | N5: Headphones | O5: =SUMIF(data[Product_Name],Analysis!N5,data[Quantity]) -> 47 | Q5: 3 | R5: =_xlfn.XLOOKUP(S5,O4:O13,$N$2:$N$11) -> Desk | S5: =LARGE($O$2:$O$11,Q5) -> 89
A6: Highest Transaction | B6: =MAX(data[Total_Amount]) -> 4499.95 | D6: Michael Brown | E6: =SUMIF(data[Customer_Name],Analysis!D6,data[Total_Amount]) -> 6169.74 | F6: =COUNTIF(data[Customer_Name],Analysis!D6) -> 9 | G6: {=_xlfn.TEXTJOIN("",TRUE,LEFT(_xlfn.TEXTSPLIT(D6," "),1))} -> MB | I6: 4 | J6: =_xlfn.XLOOKUP(K6,$E$2:$E$51,$D$2:$D$51) -> Patricia Moore | K6: =LARGE(E5:E54,I6) -> 9799.73 | N6: Laptop | O6: =SUMIF(data[Product_Name],Analysis!N6,data[Quantity]) -> 75
A7: Lowest Transaction | B7: =MIN(data[Total_Amount]) -> 59.99 | D7: Dorothy Nelson | E7: =SUMIF(data[Customer_Name],Analysis!D7,data[Total_Amount]) -> 8269.79 | F7: =COUNTIF(data[Customer_Name],Analysis!D7) -> 6 | G7: {=_xlfn.TEXTJOIN("",TRUE,LEFT(_xlfn.TEXTSPLIT(D7," "),1))} -> DN | I7: 5 | J7: =_xlfn.XLOOKUP(K7,$E$2:$E$51,$D$2:$D$51) -> Dorothy Nelson | K7: =LARGE(E6:E55,I7) -> 8269.79 | N7: Smartphone | O7: =SUMIF(data[Product_Name],Analysis!N7,data[Quantity]) -> 96
D8: Charles Allen | E8: =SUMIF(data[Customer_Name],Analysis!D8,data[Total_Amount]) -> 5089.73 | F8: =COUNTIF(data[Customer_Name],Analysis!D8) -> 9 | G8: {=_xlfn.TEXTJOIN("",TRUE,LEFT(_xlfn.TEXTSPLIT(D8," "),1))} -> CA | I8: 6 | J8: =_xlfn.XLOOKUP(K8,$E$2:$E$51,$D$2:$D$51) -> Karen Hill | K8: =LARGE(E7:E56,I8) -> 8009.77 | N8: Desk | O8: =SUMIF(data[Product_Name],Analysis!N8,data[Quantity]) -> 78
D9: Robert Thomas | E9: =SUMIF(data[Customer_Name],Analysis!D9,data[Total_Amount]) -> 3509.9 | F9: =COUNTIF(data[Customer_Name],Analysis!D9) -> 5 | G9: {=_xlfn.TEXTJOIN("",TRUE,LEFT(_xlfn.TEXTSPLIT(D9," "),1))} -> RT | I9: 7 | J9: =_xlfn.XLOOKUP(K9,$E$2:$E$51,$D$2:$D$51) -> Lawrence Reed | K9: =LARGE(E8:E57,I9) -> 6989.77 | N9: Coffee Maker | O9: =SUMIF(data[Product_Name],Analysis!N9,data[Quantity]) -> 39
A10: Payment Method | B10: Total Amount | D10: Karen Hill | E10: =SUMIF(data[Customer_Name],Analysis!D10,data[Total_Amount]) -> 8009.77 | F10: =COUNTIF(data[Customer_Name],Analysis!D10) -> 8 | G10: {=_xlfn.TEXTJOIN("",TRUE,LEFT(_xlfn.TEXTSPLIT(D10," "),1))} -> KH | I10: 8 | J10: =_xlfn.XLOOKUP(K10,$E$2:$E$51,$D$2:$D$51) -> Helen Roberts | K10: =LARGE(E9:E58,I10) -> 6459.79 | N10: Keyboard | O10: =SUMIF(data[Product_Name],Analysis!N10,data[Quantity]) -> 89
A11: {=_xlfn.UNIQUE(data[Payment_Method])} -> Cash | B11: =SUMIF(data[Payment_Method],Analysis!A11,data[Total_Amount]) -> 57427.79 | D11: Susan Green | E11: =SUMIF(data[Customer_Name],Analysis!D11,data[Total_Amount]) -> 1979.89 | F11: =COUNTIF(data[Customer_Name],Analysis!D11) -> 4 | G11: {=_xlfn.TEXTJOIN("",TRUE,LEFT(_xlfn.TEXTSPLIT(D11," "),1))} -> SG | I11: 9 | J11: =_xlfn.XLOOKUP(K11,$E$2:$E$51,$D$2:$D$51) -> Gerald Murphy | K11: =LARGE(E10:E59,I11) -> 6379.87 | N11: Office Chair | O11: =SUMIF(data[Product_Name],Analysis!N11,data[Quantity]) -> 52
A12: Credit Card | B12: =SUMIF(data[Payment_Method],Analysis!A12,data[Total_Amount]) -> 61447.96 | D12: Peter Richardson | E12: =SUMIF(data[Customer_Name],Analysis!D12,data[Total_Amount]) -> 5949.85 | F12: =COUNTIF(data[Customer_Name],Analysis!D12) -> 5 | G12: {=_xlfn.TEXTJOIN("",TRUE,LEFT(_xlfn.TEXTSPLIT(D12," "),1))} -> PR | I12: 10 | J12: =_xlfn.XLOOKUP(K12,$E$2:$E$51,$D$2:$D$51) -> Peter Richardson | K12: =LARGE(E11:E60,I12) -> 5949.85
A13: PayPal | B13: =SUMIF(data[Payment_Method],Analysis!A13,data[Total_Amount]) -> 58198.41 | D13: Dennis Gray | E13: =SUMIF(data[Customer_Name],Analysis!D13,data[Total_Amount]) -> 479.92 | F13: =COUNTIF(data[Customer_Name],Analysis!D13) -> 2 | G13: {=_xlfn.TEXTJOIN("",TRUE,LEFT(_xlfn.TEXTSPLIT(D13," "),1))} -> DG
A14: Debit Card | B14: =SUMIF(data[Payment_Method],Analysis!A14,data[Total_Amount]) -> 52118.31 | D14: Michelle Rogers | E14: =SUMIF(data[Customer_Name],Analysis!D14,data[Total_Amount]) -> 4199.94 | F14: =COUNTIF(data[Customer_Name],Analysis!D14) -> 2 | G14: {=_xlfn.TEXTJOIN("",TRUE,LEFT(_xlfn.TEXTSPLIT(D14," "),1))} -> MR
A15: Total | B15: =SUM(B11:B14) -> 229192.47 | D15: George Adams | E15: =SUMIF(data[Customer_Name],Analysis!D15,data[Total_Amount]) -> 3779.93 | F15: =COUNTIF(data[Customer_Name],Analysis!D15) -> 3 | G15: {=_xlfn.TEXTJOIN("",TRUE,LEFT(_xlfn.TEXTSPLIT(D15," "),1))} -> GA
D16: Mark Carter | E16: =SUMIF(data[Customer_Name],Analysis!D16,data[Total_Amount]) -> 15659.65 | F16: =COUNTIF(data[Customer_Name],Analysis!D16) -> 12 | G16: {=_xlfn.TEXTJOIN("",TRUE,LEFT(_xlfn.TEXTSPLIT(D16," "),1))} -> MC | I16: High-Value Customers (>5000) | N16: Two Lists & Extract Matching Names
D17: Maria Garcia | E17: =SUMIF(data[Customer_Name],Analysis!D17,data[Total_Amount]) -> 1909.93 | F17: =COUNTIF(data[Customer_Name],Analysis!D17) -> 4 | G17: {=_xlfn.TEXTJOIN("",TRUE,LEFT(_xlfn.TEXTSPLIT(D17," "),1))} -> MG | I17: {=_xlfn._xlws.FILTER(D2:F51,E2:E51 > 5000)} -> Paul Baker | J17: 8309.74 | K17: 8 | N17: List A | O17: List B | P17: List C | Q17: Maching Name
A18: Scenario Manager | D18: Virginia Sanders | E18: =SUMIF(data[Customer_Name],Analysis!D18,data[Total_Amount]) -> 4789.79 | F18: =COUNTIF(data[Customer_Name],Analysis!D18) -> 6 | G18: {=_xlfn.TEXTJOIN("",TRUE,LEFT(_xlfn.TEXTSPLIT(D18," "),1))} -> VS | I18: Joseph Jackson | J18: 6949.84 | K18: 5 | N18: Arjun | O18: Neha | P18: Arjun | Q18: {=_xlfn._xlws.FILTER(N18:N24,(COUNTIF(O18:O24,N18:N24)) * (COUNTIF(P18:P24,N18:N24)) > 0)} -> Arjun
A19: Total Revenue | B19: =SUM(Data!N:N) -> 229192.47 | D19: Barbara Young | E19: =SUMIF(data[Customer_Name],Analysis!D19,data[Total_Amount]) -> 10649.8 | F19: =COUNTIF(data[Customer_Name],Analysis!D19) -> 5 | G19: {=_xlfn.TEXTJOIN("",TRUE,LEFT(_xlfn.TEXTSPLIT(D19," "),1))} -> BY | I19: Michael Brown | J19: 6169.74 | K19: 9 | N19: Riya | O19: Arjun | P19: Riya | Q19: Meera
A20: 0.1 | B20: =$B$19*(1+A20) -> 252111.72 | D20: Patricia Moore | E20: =SUMIF(data[Customer_Name],Analysis!D20,data[Total_Amount]) -> 9799.73 | F20: =COUNTIF(data[Customer_Name],Analysis!D20) -> 8 | G20: {=_xlfn.TEXTJOIN("",TRUE,LEFT(_xlfn.TEXTSPLIT(D20," "),1))} -> PM | I20: Dorothy Nelson | J20: 8269.79 | K20: 6 | N20: Karan | O20: Meera | P20: Karan | Q20: Rohan
D21: Cynthia Price | E21: =SUMIF(data[Customer_Name],Analysis!D21,data[Total_Amount]) -> 3769.83 | F21: =COUNTIF(data[Customer_Name],Analysis!D21) -> 5 | G21: {=_xlfn.TEXTJOIN("",TRUE,LEFT(_xlfn.TEXTSPLIT(D21," "),1))} -> CP | I21: Charles Allen | J21: 5089.73 | K21: 9 | N21: Meera | O21: Rohan | P21: Meera | Q21: Ananya
D22: Nancy Collins | E22: =SUMIF(data[Customer_Name],Analysis!D22,data[Total_Amount]) -> 4189.77 | F22: =COUNTIF(data[Customer_Name],Analysis!D22) -> 6 | G22: {=_xlfn.TEXTJOIN("",TRUE,LEFT(_xlfn.TEXTSPLIT(D22," "),1))} -> NC | I22: Karen Hill | J22: 8009.77 | K22: 8 | N22: Rohan | O22: Kavya | P22: Rohan
A23: Goal Seek (₹3,50,000 revenue) | D23: Linda Martin | E23: =SUMIF(data[Customer_Name],Analysis!D23,data[Total_Amount]) -> 1289.9 | F23: =COUNTIF(data[Customer_Name],Analysis!D23) -> 4 | G23: {=_xlfn.TEXTJOIN("",TRUE,LEFT(_xlfn.TEXTSPLIT(D23," "),1))} -> LM | I23: Peter Richardson | J23: 5949.85 | K23: 5 | N23: Ananya | O23: Ananya | P23: Ananya
A24: Current Total Sales | B24: =SUM(Data!N:N) -> 229192.47 | D24: Helen Roberts | E24: =SUMIF(data[Customer_Name],Analysis!D24,data[Total_Amount]) -> 6459.79 | F24: =COUNTIF(data[Customer_Name],Analysis!D24) -> 7 | G24: {=_xlfn.TEXTJOIN("",TRUE,LEFT(_xlfn.TEXTSPLIT(D24," "),1))} -> HR | I24: Mark Carter | J24: 15659.65 | K24: 12 | N24: Vikram | O24: Dev | P24: Prit
A25: Growth % | B25: 0.52710078 | D25: Edward Mitchell | E25: =SUMIF(data[Customer_Name],Analysis!D25,data[Total_Amount]) -> 11919.77 | F25: =COUNTIF(data[Customer_Name],Analysis!D25) -> 6 | G25: {=_xlfn.TEXTJOIN("",TRUE,LEFT(_xlfn.TEXTSPLIT(D25," "),1))} -> EM | I25: Barbara Young | J25: 10649.8 | K25: 5
A26: Projected Sales | B26: =B24*(1+B25) -> 350000 | D26: Lisa Anderson | E26: =SUMIF(data[Customer_Name],Analysis!D26,data[Total_Amount]) -> 2039.8 | F26: =COUNTIF(data[Customer_Name],Analysis!D26) -> 5 | G26: {=_xlfn.TEXTJOIN("",TRUE,LEFT(_xlfn.TEXTSPLIT(D26," "),1))} -> LA | I26: Patricia Moore | J26: 9799.73 | K26: 8
D27: Emma Wilson | E27: =SUMIF(data[Customer_Name],Analysis!D27,data[Total_Amount]) -> 1229.88 | F27: =COUNTIF(data[Customer_Name],Analysis!D27) -> 5 | G27: {=_xlfn.TEXTJOIN("",TRUE,LEFT(_xlfn.TEXTSPLIT(D27," "),1))} -> EW | I27: Helen Roberts | J27: 6459.79 | K27: 7
D28: Steven Turner | E28: =SUMIF(data[Customer_Name],Analysis!D28,data[Total_Amount]) -> 2649.83 | F28: =COUNTIF(data[Customer_Name],Analysis!D28) -> 6 | G28: {=_xlfn.TEXTJOIN("",TRUE,LEFT(_xlfn.TEXTSPLIT(D28," "),1))} -> ST | I28: Edward Mitchell | J28: 11919.77 | K28: 6
D29: Jennifer Taylor | E29: =SUMIF(data[Customer_Name],Analysis!D29,data[Total_Amount]) -> 4739.85 | F29: =COUNTIF(data[Customer_Name],Analysis!D29) -> 4 | G29: {=_xlfn.TEXTJOIN("",TRUE,LEFT(_xlfn.TEXTSPLIT(D29," "),1))} -> JT | I29: Harry Morgan | J29: 5519.89 | K29: 4
D30: Harry Morgan | E30: =SUMIF(data[Customer_Name],Analysis!D30,data[Total_Amount]) -> 5519.89 | F30: =COUNTIF(data[Customer_Name],Analysis!D30) -> 4 | G30: {=_xlfn.TEXTJOIN("",TRUE,LEFT(_xlfn.TEXTSPLIT(D30," "),1))} -> HM | I30: Daniel King | J30: 7309.8 | K30: 7
D31: Daniel King | E31: =SUMIF(data[Customer_Name],Analysis!D31,data[Total_Amount]) -> 7309.8 | F31: =COUNTIF(data[Customer_Name],Analysis!D31) -> 7 | G31: {=_xlfn.TEXTJOIN("",TRUE,LEFT(_xlfn.TEXTSPLIT(D31," "),1))} -> DK | I31: Sharon Butler | J31: 5619.87 | K31: 6
D32: Sharon Butler | E32: =SUMIF(data[Customer_Name],Analysis!D32,data[Total_Amount]) -> 5619.87 | F32: =COUNTIF(data[Customer_Name],Analysis!D32) -> 6 | G32: {=_xlfn.TEXTJOIN("",TRUE,LEFT(_xlfn.TEXTSPLIT(D32," "),1))} -> SB | I32: Sarah Davis | J32: 5499.81 | K32: 5
D33: Sarah Davis | E33: =SUMIF(data[Customer_Name],Analysis!D33,data[Total_Amount]) -> 5499.81 | F33: =COUNTIF(data[Customer_Name],Analysis!D33) -> 5 | G33: {=_xlfn.TEXTJOIN("",TRUE,LEFT(_xlfn.TEXTSPLIT(D33," "),1))} -> SD | I33: Betty Campbell | J33: 5649.84 | K33: 5
D34: Betty Campbell | E34: =SUMIF(data[Customer_Name],Analysis!D34,data[Total_Amount]) -> 5649.84 | F34: =COUNTIF(data[Customer_Name],Analysis!D34) -> 5 | G34: {=_xlfn.TEXTJOIN("",TRUE,LEFT(_xlfn.TEXTSPLIT(D34," "),1))} -> BC | I34: Gerald Murphy | J34: 6379.87 | K34: 4
D35: Julie Foster | E35: =SUMIF(data[Customer_Name],Analysis!D35,data[Total_Amount]) -> 239.96 | F35: =COUNTIF(data[Customer_Name],Analysis!D35) -> 1 | G35: {=_xlfn.TEXTJOIN("",TRUE,LEFT(_xlfn.TEXTSPLIT(D35," "),1))} -> JF | I35: Lawrence Reed | J35: 6989.77 | K35: 8
D36: Raymond Ross | E36: =SUMIF(data[Customer_Name],Analysis!D36,data[Total_Amount]) -> 3669.85 | F36: =COUNTIF(data[Customer_Name],Analysis!D36) -> 4 | G36: {=_xlfn.TEXTJOIN("",TRUE,LEFT(_xlfn.TEXTSPLIT(D36," "),1))} -> RR | I36: Sandra Phillips | J36: 6349.83 | K36: 5
D37: David Martinez | E37: =SUMIF(data[Customer_Name],Analysis!D37,data[Total_Amount]) -> 1809.84 | F37: =COUNTIF(data[Customer_Name],Analysis!D37) -> 6 | G37: {=_xlfn.TEXTJOIN("",TRUE,LEFT(_xlfn.TEXTSPLIT(D37," "),1))} -> DM
D38: Margaret Wright | E38: =SUMIF(data[Customer_Name],Analysis!D38,data[Total_Amount]) -> 2099.88 | F38: =COUNTIF(data[Customer_Name],Analysis!D38) -> 4 | G38: {=_xlfn.TEXTJOIN("",TRUE,LEFT(_xlfn.TEXTSPLIT(D38," "),1))} -> MW
D39: Frank Torres | E39: =SUMIF(data[Customer_Name],Analysis!D39,data[Total_Amount]) -> 1479.91 | F39: =COUNTIF(data[Customer_Name],Analysis!D39) -> 5 | G39: {=_xlfn.TEXTJOIN("",TRUE,LEFT(_xlfn.TEXTSPLIT(D39," "),1))} -> FT
D40: Gerald Murphy | E40: =SUMIF(data[Customer_Name],Analysis!D40,data[Total_Amount]) -> 6379.87 | F40: =COUNTIF(data[Customer_Name],Analysis!D40) -> 4 | G40: {=_xlfn.TEXTJOIN("",TRUE,LEFT(_xlfn.TEXTSPLIT(D40," "),1))} -> GM
...

Sheet Scenario Summary
B2: Scenario Summary
D3: Current Values: | E3: Low Growth | F3: Medium Growth | G3: High Growth | H3: Very High Growth
E4: Created by Ayush Donga on 08-10-2026 | F4: Created by Ayush Donga on 08-10-2026 | G4: Created by Ayush Donga on 08-10-2026 | H4: Created by Ayush Donga on 08-10-2026
B5: Changing Cells:
C6: $A$20 | D6: 0.1 | E6: 0.05 | F6: 0.1 | G6: 0.15 | H6: 0.2
B7: Result Cells:
C8: $B$20 | D8: 252111.72 | E8: 240652.09 | F8: 252111.72 | G8: 263571.34 | H8: 275030.96
B9: Notes: Current Values column represents values of changing cells at
B10: time Scenario Summary Report was created. Changing cells for each
B11: scenario are highlighted in gray.

Sheet Linear Regression
A1: SUMMARY OUTPUT
A3: Regression Statistics
A4: Multiple R | B4: 0.45809869
A5: R Square | B5: 0.20985441
A6: Adjusted R Square | B6: 0.20665544
A7: Standard Error | B7: 921.40854
A8: Observations | B8: 249
A10: ANOVA
B11: df | C11: SS | D11: MS | E11: F | F11: Significance F
A12: Regression | B12: 1 | C12: 55694513 | D12: 55694513 | E12: 65.60062 | F12: 2.5391277e-14
A13: Residual | B13: 247 | C13: 2.0970144e+08 | D13: 848993.7
A14: Total | B14: 248 | C14: 2.6539596e+08
B16: Coefficients | C16: Standard Error | D16: t Stat | E16: P-value | F16: Lower 95% | G16: Upper 95% | H16: Lower 95.0% | I16: Upper 95.0%
A17: Intercept | B17: -148.18856 | C17: 143.94399 | D17: -1.0294877 | E17: 0.30425761 | F17: -431.70277 | G17: 135.32564 | H17: -431.70277 | I17: 135.32564
A18: 3 | B18: 353.7886 | C18: 43.680728 | D18: 8.0994209 | E18: 2.5391277e-14 | F18: 267.7544 | G18: 439.82281 | H18: 267.7544 | I18: 439.82281

Sheet Pivot Table
A1: Row Labels | B1: Sum of Total_Amount | G1: Row Labels | H1: Sum of Total_Amount | J1: Row Labels | K1: Sum of Total_Amount
A2: Coffee Maker | B2: 3119.61 | G2: Central | H2: 41288.34 | J2: Basic | K2: 62177.81
A3: Blender | B3: 5219.13 | G3: East | H3: 59288.39 | J3: Premium | K3: 84657.12
A4: Headphones | B4: 7049.53 | G4: North | H4: 50808.31 | J4: Standard | K4: 82357.54
A5: Keyboard | B5: 8009.11 | G5: South | H5: 36398.75 | J5: Grand Total | K5: 229192.47
A6: Office Chair | B6: 10399.48 | G6: West | H6: 41408.68
A7: Bookshelf | B7: 15298.98 | G7: Grand Total | H7: 229192.47
A8: Monitor | B8: 21999.12
A9: Desk | B9: 23399.22 | D9: Row Labels | E9: Sum of Total_Amount
A10: Smartphone | B10: 67199.04 | D10: 1 | E10: 25799.15 | G10: Sum of Quantity | H10: Column Labels
A11: Laptop | B11: 67499.25 | D11: 2 | E11: 16069.38 | G11: Row Labels | H11: Appliances | I11: Electronics | J11: Furniture | K11: Grand Total
A12: Grand Total | B12: 229192.47 | D12: 3 | E12: 19899.38 | G12: Central | H12: 29 | I12: 67 | J12: 70 | K12: 166
D13: 4 | E13: 27899.16 | G13: East | H13: 33 | I13: 99 | J13: 29 | K13: 161
D14: 5 | E14: 17039.35 | G14: North | H14: 16 | I14: 96 | J14: 57 | K14: 169
A15: Row Labels | B15: Sum of Total_Amount | D15: 6 | E15: 19299.45 | G15: South | H15: 17 | I15: 68 | J15: 40 | K15: 125
A16: Cash | B16: 57427.79 | D16: 7 | E16: 18479.4 | G16: West | H16: 31 | I16: 65 | J16: 36 | K16: 132
A17: Credit Card | B17: 61447.96 | D17: 8 | E17: 15759.43 | G17: Grand Total | H17: 126 | I17: 395 | J17: 232 | K17: 753
A18: Debit Card | B18: 52118.31 | D18: 9 | E18: 12989.51
A19: PayPal | B19: 58198.41 | D19: 10 | E19: 20609.52
A20: Grand Total | B20: 229192.47 | D20: 11 | E20: 12309.44 | G20: Count of Total_Amount | H20: Column Labels
D21: 12 | E21: 23039.3 | G21: Row Labels | H21: Basic | I21: Premium | J21: Standard | K21: Grand Total
D22: Grand Total | E22: 229192.47 | G22: Cash | H22: 22 | I22: 31 | J22: 23 | K22: 76
G23: Credit Card | H23: 20 | I23: 29 | J23: 19 | K23: 68
G24: Debit Card | H24: 12 | I24: 18 | J24: 24 | K24: 54
G25: PayPal | H25: 20 | I25: 17 | J25: 15 | K25: 52
G26: Grand Total | H26: 74 | I26: 95 | J26: 81 | K26: 250

Sheet Dashboard
B2: SALES PERFORMANCE DASHBOARD
B3: ="Transactions "&TEXT(MIN([1]Data!B2:B251),"mmm yyyy")&" to "&TEXT(MAX([1]Data!B2:B251),"mmm yyyy")&" | Source: Pivot Table sheet | Amounts in $" -> Transactions Apr 2024 to Apr 2025 | Source: Pivot Table sheet | Amounts in $
B7: TOTAL REVENUE | E7: TRANSACTIONS | H7: UNITS SOLD | K7: AVG ORDER VALUE | N7: TOP PRODUCT
B8: =Analysis!B2 -> 229192.47 | E8: =Analysis!B3 -> 250 | H8: =Analysis!B4 -> 753 | K8: =IFERROR(B8/E8,0) -> 916.76988 | N8: =Analysis!R3 -> Bookshelf
B74: 📌 Key Insights
B76: 💰 Revenue: Total revenue indicates the overall sales performance of the business.
B77: 👑 Top Customers: High-value and frequent customers contribute significantly to revenue.
B78: 📦 Top Products: Best-selling products should receive priority in inventory and promotions.
B79: 🌍 Regional Performance: The highest-performing region contributes the most to overall sales.
B80: 📈 Sales Trend: Monthly sales trends highlight periods of growth and decline.
B82: 🎯 Recommendations
B84: Focus on retaining high-value customers through loyalty offers.
B85: Maintain sufficient stock of top-selling products.
B86: Improve marketing in low-performing regions.
B87: Use customer segments for targeted promotions.
B88: Monitor monthly sales trends for better planning.
